const x = 10

try {
  x = 2
} catch (err) {
  console.log(err)
}

console.log('continuando o codigo...')
